<!DOCTYPE html>
<html>
    <body>
        <script>
            const promiseGet=url=>{
                return new Promise((resolve,reject)=>{
                    const xhr=new XMLHttpRequest();
                    xhr.open('GET',url);
                    xhr.send();
                    xhr.onload=()=>{
                        if(xhr.status===200){
                            resolve(JSON.parse(xhr.response));
                        }else{
                            reject(new Error(xhr.status));
                        }
                    }
                })
            }
            const wrongUrl='https://jsonplaceholder.typicode.com/XXX/1';
            promiseGet(wrongUrl).then(
                res=>console.log(res),
                err=>console.error(err)
            )
            /**
             * 비동기 함수 get은 프로미스를 반환한다. 비동기 처리 결과에 대한 후속 처리는 프로미스가 제공하는
             * 후속 처리 메서드 then, catch, finally를 사용하여 수행한다. 비동기 처리에서 발생한 에러는
             * then 메서드의 두 번째 콜백 함수로 처리할 수 있다.
             * 비동기 처리에서 발생한 에러는 프로미스의 후속 처리 메서드 catch를 사용해 처리할 수도 있다.
             */
            promiseGet(wrongUrl)
                .then(res=>console.log(res))
                .catch(err=>console.error(err));
            //위와 동일
            promiseGet(wrongUrl)
                .then(res=>console.log(res))
                .then(undefined,err=>console.error(err));
            //단, then 메서드의 두 번째 콜백 함수는 첫 번째 콜백 함수에서 발생한 에러를 캐치하지 못하고 코드가 복잡해져서 가독성이 좋지 않다.
            promiseGet('https://jsonplaceholder.typicode.com/todos/1').then(
                res=>console.xxx(res),
                err=>console.error(err)
            );
            //catch 메서드를 모든 then메서드를 호출한 이후에 호출하면 비동기 처리에서 발생한 에러(rejected 상태)뿐만 아니라 then메서드 내부에서 발생한 에러까지 모두 캐치할 수 있다.
            promiseGet('https://jsonplaceholder.typicode.com/todos/1')
                .then(res=>console.xxx(res))
                .catch(err=>console.error(err));
        </script>
    </body>
</html>